<?xml version="1.0" encoding="utf-8"?>
<!-- =================================================================================== -->
<!-- |    This document was autogenerated by xacro from tas_car.urdf.xacro             | -->
<!-- |    EDITING THIS FILE BY HAND IS NOT RECOMMENDED                                 | -->
<!-- =================================================================================== -->
<robot name="vacuum_bot">
  <!-- Include constants, configs, meshes etc. -->
  <!-- robot visual materials -->
  <material name="Grey">
    <color rgba="0.7 0.7 0.7 1.0"/>
  </material>
  <material name="Green">
    <color rgba="0.0 1.0 0.0 1.0"/>
  </material>
  <material name="Red">
    <color rgba="1.0 0.0 0.0 1.0"/>
  </material>
  <!-- Robot creation macro -->
  <link name="base_footprint"/>
  <link name="base">
    <visual>
      <origin rpy="0 0 0" xyz="0 0 0"/>
      <geometry>
        <mesh filename="package://robot_sim/urdf/meshes/model_base_reduced.dae"/>
      </geometry>
    </visual>
    <collision>
      <origin rpy="0 0 0" xyz="0 0 0"/>
      <geometry>
        <mesh filename="package://robot_sim/urdf/meshes/model_base_reduced.dae"/>
      </geometry>
    </collision>
    <inertial>
      <mass value="2.0"/>
      <inertia ixx="0.37267" ixy="0.535" ixz="0.27612" iyy="0.60173" iyz="0.37267" izz="0.5256"/>
    </inertial>
  </link>
  <joint name="footprint_base_joint" type="fixed">
    <axis rpy="0 0 0" xyz="0 0 1"/>
    <origin rpy="0 0 0" xyz="0 0 0.1"/>
    <parent link="base_footprint"/>
    <child link="base"/>
  </joint>
  <link name="r_f_wheel">
    <visual>
      <origin rpy="0 0 0" xyz="0 0 0"/>
      <geometry>
        <mesh filename="package://robot_sim/urdf/meshes/model_wheel_right.dae"/>
      </geometry>
    </visual>
    <collision>
      <geometry>
        <mesh filename="package://robot_sim/urdf/meshes/model_wheel_right_collision.dae"/>
      </geometry>
    </collision>
    <inertial>
      <mass value="0.0482"/>
      <origin xyz="0 0 0"/>
      <inertia ixx="3.745e-7" ixy="6.657e-7" ixz="3.28e-7" iyy="3.28e-7" iyz="3.745e-7" izz="6.657e-7"/>
    </inertial>
  </link>
  <joint name="base_r_f_wheel_joint" type="continuous">
    <axis rpy="0 0 0" xyz="0 0 1"/>
    <origin rpy="1.570796325 0 0" xyz="0.172 0.19189 -0.009168"/>
    <parent link="base"/>
    <child link="r_f_wheel"/>
  </joint>
  <link name="l_f_wheel">
    <visual>
      <origin rpy="0 0 0" xyz="0 0 0"/>
      <geometry>
        <mesh filename="package://robot_sim/urdf/meshes/model_wheel_left.dae"/>
      </geometry>
    </visual>
    <collision>
      <geometry>
        <mesh filename="package://robot_sim/urdf/meshes/model_wheel_left_collision.dae"/>
      </geometry>
    </collision>
    <inertial>
      <mass value="0.0482"/>
      <origin xyz="0 0 0"/>
      <inertia ixx="3.745e-7" ixy="6.657e-7" ixz="3.28e-7" iyy="3.28e-7" iyz="3.745e-7" izz="6.657e-7"/>
    </inertial>
  </link>
  <joint name="base_l_f_wheel_joint" type="continuous">
    <axis rpy="0 0 0" xyz="0 0 1"/>
    <origin rpy="1.570796325 0 0" xyz="0.172 -0.19189 -0.009168"/>
    <parent link="base"/>
    <child link="l_f_wheel"/>
  </joint>
  <link name="r_b_wheel">
    <visual>
      <origin rpy="0 0 0" xyz="0 0 0"/>
      <geometry>
        <mesh filename="package://robot_sim/urdf/meshes/model_wheel_right.dae"/>
      </geometry>
    </visual>
    <collision>
      <geometry>
        <mesh filename="package://robot_sim/urdf/meshes/model_wheel_right_collision.dae"/>
      </geometry>
    </collision>
    <inertial>
      <mass value="0.0482"/>
      <origin xyz="0 0 0"/>
      <inertia ixx="3.745e-7" ixy="6.657e-7" ixz="3.28e-7" iyy="3.28e-7" iyz="3.745e-7" izz="6.657e-7"/>
    </inertial>
  </link>
  <joint name="base_r_b_wheel_joint" type="continuous">
    <axis rpy="0 0 0" xyz="0 0 1"/>
    <origin rpy="1.570796325 0 0" xyz="-0.18673 0.19189 -0.009168"/>
    <parent link="base"/>
    <child link="r_b_wheel"/>
  </joint>
  <link name="l_b_wheel">
    <visual>
      <origin rpy="0 0 0" xyz="0 0 0"/>
      <geometry>
        <mesh filename="package://robot_sim/urdf/meshes/model_wheel_left.dae"/>
      </geometry>
    </visual>
    <collision>
      <geometry>
        <mesh filename="package://robot_sim/urdf/meshes/model_wheel_left_collision.dae"/>
      </geometry>
    </collision>
    <inertial>
      <mass value="0.0482"/>
      <origin xyz="0 0 0"/>
      <inertia ixx="3.745e-7" ixy="6.657e-7" ixz="3.28e-7" iyy="3.28e-7" iyz="3.745e-7" izz="6.657e-7"/>
    </inertial>
  </link>
  <joint name="base_l_b_wheel_joint" type="continuous">
    <axis rpy="0 0 0" xyz="0 0 1"/>
    <origin rpy="1.570796325 0 0" xyz="-0.18673 -0.19189 -0.009168"/>
    <parent link="base"/>
    <child link="l_b_wheel"/>
  </joint>
  <link name="hokuyo1_link">
    <visual>
      <origin xyz="0 0 -0.025"/>
      <geometry>
        <mesh filename="package://robot_sim/urdf/meshes/hokuyo.dae"/>
      </geometry>
      <material name="Green"/>
    </visual>
    <collision>
      <origin xyz="0 0 -0.025"/>
      <geometry>
        <box size="0.05 0.05 0.07"/>
      </geometry>
    </collision>
    <inertial>
      <mass value="0.001"/>
      <origin xyz="0 0 0"/>
      <inertia ixx="0.0001" ixy="0.0" ixz="0.0" iyy="0.0001" iyz="0.0" izz="0.0001"/>
    </inertial>
  </link>
  <gazebo reference="hokuyo1_link">
    <sensor name="head_hokuyo_sensor" type="ray">
      <pose>0 0 0 0 0 0</pose>
      <visualize>true</visualize>
      <update_rate>40</update_rate>
      <ray>
        <scan>
          <horizontal>
            <samples>720</samples>
            <resolution>0.25</resolution>
            <min_angle>-1.5</min_angle>
            <max_angle>1.5</max_angle>
          </horizontal>
        </scan>
        <range>
          <min>0.10</min>
          <max>30.0</max>
          <resolution>0.01</resolution>
        </range>
        <noise>
          <type>gaussian</type>
          <!-- Noise parameters based on published spec for Hokuyo laser
                 achieving "+-30mm" accuracy at range < 10m.  A mean of 0.0m and
                 stddev of 0.01m will put 99.7% of samples within 0.03m of the true
                 reading. -->
          <mean>0.0</mean>
          <stddev>0.01</stddev>
        </noise>
      </ray>
      <plugin filename="libgazebo_ros_laser.so" name="gazebo_ros_head_hokuyo_controller">
        <topicName>/laserscan</topicName>
        <frameName>hokuyo1_link</frameName>
      </plugin>
    </sensor>
  </gazebo>
  <joint name="hokuyo1_joint" type="fixed">
    <origin rpy="0 0 0" xyz="0.28 0.0 0.18"/>
    <axis rpy="0 0 0" xyz="0 0 1"/>
    <parent link="base"/>
    <child link="hokuyo1_link"/>
  </joint>
  <link name="hokuyo2_link">
    <visual>
      <origin xyz="0 0 -0.025"/>
      <geometry>
        <mesh filename="package://robot_sim/urdf/meshes/hokuyo.dae"/>
      </geometry>
      <material name="Green"/>
    </visual>
    <collision>
      <origin xyz="0 0 -0.025"/>
      <geometry>
        <box size="0.05 0.05 0.07"/>
      </geometry>
    </collision>
    <inertial>
      <mass value="0.001"/>
      <origin xyz="0 0 0"/>
      <inertia ixx="0.0001" ixy="0.0" ixz="0.0" iyy="0.0001" iyz="0.0" izz="0.0001"/>
    </inertial>
  </link>
  <gazebo reference="hokuyo2_link">
    <sensor name="head_hokuyo_sensor" type="ray">
      <pose>0 0 0 0 0 0</pose>
      <visualize>true</visualize>
      <update_rate>40</update_rate>
      <ray>
        <scan>
          <horizontal>
            <samples>720</samples>
            <resolution>0.25</resolution>
            <min_angle>-1.5</min_angle>
            <max_angle>1.5</max_angle>
          </horizontal>
        </scan>
        <range>
          <min>0.10</min>
          <max>30.0</max>
          <resolution>0.01</resolution>
        </range>
        <noise>
          <type>gaussian</type>
          <!-- Noise parameters based on published spec for Hokuyo laser
                 achieving "+-30mm" accuracy at range < 10m.  A mean of 0.0m and
                 stddev of 0.01m will put 99.7% of samples within 0.03m of the true
                 reading. -->
          <mean>0.0</mean>
          <stddev>0.01</stddev>
        </noise>
      </ray>
      <plugin filename="libgazebo_ros_laser.so" name="gazebo_ros_head_hokuyo_controller">
        <topicName>/laserscan</topicName>
        <frameName>hokuyo2_link</frameName>
      </plugin>
    </sensor>
  </gazebo>
  <joint name="hokuyo2_joint" type="fixed">
    <origin rpy="0 0 3.14159265" xyz="-0.28 0.0 0.1"/>
    <axis rpy="0 0 0" xyz="0 0 1"/>
    <parent link="base"/>
    <child link="hokuyo2_link"/>
  </joint>
  <link name="imu_1">
    <visual>
      <origin rpy="0 0 0" xyz="0 0 0"/>
      <geometry>
        <box size="0.05 0.05 0.02"/>
      </geometry>
    </visual>
    <collision>
      <origin rpy="0 0 0" xyz="0 0 0"/>
      <geometry>
        <box size="0.05 0.05 0.02"/>
      </geometry>
    </collision>
    <inertial>
      <mass value="0.2"/>
      <inertia ixx="0.01" ixy="0" ixz="0" iyy="0.01" iyz="0" izz="0.01"/>
    </inertial>
  </link>
  <gazebo reference="imu_1">
    <material>Gazebo/Grey</material>
  </gazebo>
  <joint name="imu_1_joint" type="fixed">
    <axis rpy="0 0 0" xyz="0 0 1"/>
    <origin rpy="0 0 0" xyz="0.08 0.124 0.115"/>
    <parent link="base"/>
    <child link="imu_1"/>
  </joint>
  <gazebo reference="imu_link">
    <gravity>true</gravity>
    <sensor name="imu_sensor" type="imu">
      <always_on>true</always_on>
      <update_rate>100</update_rate>
      <visualize>true</visualize>
      <topic>__default_topic__</topic>
      <plugin filename="libgazebo_ros_imu_sensor.so" name="imu_plugin">
        <topicName>imu</topicName>
        <bodyName>imu_1</bodyName>
        <updateRateHZ>10.0</updateRateHZ>
        <gaussianNoise>0.0</gaussianNoise>
        <xyzOffset>0 0 0</xyzOffset>
        <rpyOffset>0 0 0</rpyOffset>
        <frameName>imu_1</frameName>
      </plugin>
      <pose>0 0 0 0 0 0</pose>
    </sensor>
  </gazebo>
  <transmission name="trans_base_r_b_wheel_joint">
    <type>transmission_interface/SimpleTransmission</type>
    <joint name="base_r_b_wheel_joint">
      <hardwareInterface>hardware_interface/EffortJointInterface</hardwareInterface>
    </joint>
    <actuator name="base_r_b_wheel_joint_motor">
      <hardwareInterface>hardware_interface/EffortJointInterface</hardwareInterface>
      <mechanicalReduction>1</mechanicalReduction>
    </actuator>
  </transmission>
  <transmission name="trans_base_l_b_wheel_joint">
    <type>transmission_interface/SimpleTransmission</type>
    <joint name="base_l_b_wheel_joint">
      <hardwareInterface>hardware_interface/EffortJointInterface</hardwareInterface>
    </joint>
    <actuator name="base_l_b_wheel_joint_motor">
      <hardwareInterface>hardware_interface/EffortJointInterface</hardwareInterface>
      <mechanicalReduction>1</mechanicalReduction>
    </actuator>
  </transmission>
  <gazebo>
    <plugin filename="libgazebo_ros_control.so" name="gazebo_ros_control">
      <robotNamespace>/tas_car</robotNamespace>
    </plugin>
  </gazebo>
</robot>
